Workbook
Name Beg_Bal: '1.A. Loan Calculators(JACINTO)'!$C$17:$C$497
Name Extra_Pay: '1.A. Loan Calculators(JACINTO)'!$E$17:$E$497
Name Int: '1.A. Loan Calculators(JACINTO)'!$H$17:$H$497
Name Interest_Rate: '1.A. Loan Calculators(JACINTO)'!$D$6
Name Interest_Rate: #REF!
Name Interest_Rate: #REF!
Name Interest_Rate: #REF!
Name Interest_Rate: #REF!
Name K: #REF!
Name K: #REF!
Name K: #REF!
Name K: #REF!
Name KL: #REF!
Name KL: #REF!
Name KL: #REF!
Name KL: #REF!
Name L: #REF!
Name L: #REF!
Name L: #REF!
Name L: #REF!
Name Last_Row: IF([1]TRIAL!Values_Entered,[1]TRIAL!Header_Row+[1]TRIAL!Number_of_Payments,[1]TRIAL!Header_Row)
Name Last_Row: IF([1]TRIAL!Values_Entered,[1]TRIAL!Header_Row+[1]TRIAL!Number_of_Payments,[1]TRIAL!Header_Row)
Name Loan_Amount: '1.A. Loan Calculators(JACINTO)'!$D$5
Name Loan_Amount: #REF!
Name Loan_Amount: #REF!
Name Loan_Amount: #REF!
Name Loan_Amount: #REF!
Name Loan_Start: '1.A. Loan Calculators(JACINTO)'!$D$9
Name Loan_Years: '1.A. Loan Calculators(JACINTO)'!$D$7
Name M: #REF!
Name M: #REF!
Name M: #REF!
Name M: #REF!
Name Num_Pmt_Per_Year: '1.A. Loan Calculators(JACINTO)'!$D$8
Name Num_Pmt_Per_Year: #REF!
Name Num_Pmt_Per_Year: #REF!
Name Num_Pmt_Per_Year: #REF!
Name Num_Pmt_Per_Year: #REF!
Name Number_of_Payments: MATCH(0.01,[1]TRIAL!End_Bal,-1)+1
Name Pay_Num: '1.A. Loan Calculators(JACINTO)'!$A$17:$A$497
Name Princ: '1.A. Loan Calculators(JACINTO)'!$G$17:$G$497
Name Sched_Pay: '1.A. Loan Calculators(JACINTO)'!$D$17:$D$497
Name Scheduled_Extra_Payments: '1.A. Loan Calculators(JACINTO)'!$D$10
Name Scheduled_Monthly_Payment: '1.A. Loan Calculators(JACINTO)'!$J$5
Name Scheduled_Monthly_Payment: #REF!
Name Scheduled_Monthly_Payment: #REF!
Name Scheduled_Monthly_Payment: #REF!
Name Scheduled_Monthly_Payment: #REF!
Name Total_Pay: '1.A. Loan Calculators(JACINTO)'!$F$17:$F$497
Name Values_Entered: IF([1]TRIAL!Loan_Amount*[1]TRIAL!Interest_Rate*[1]TRIAL!Loan_Years*[1]TRIAL!Loan_Start>0,1,0)
Name Values_Entered: IF([1]TRIAL!Loan_Amount*[1]TRIAL!Interest_Rate*[1]TRIAL!Loan_Years*[1]TRIAL!Loan_Start>0,1,0)

Sheet 1.C. FT (OLASI)
B2: 1-306-132527 | C2: LAGUNA ELECTRONICS INC MULTI- | D2: =#REF! -> #REF! | E2: =#REF! -> #REF!
C3: PURPOSE COOPERATIVE
A5: =#REF! -> #REF! | D5: COOPERATIVE LOAN
A7: =#REF! -> #REF!
A10: JOSE EDGARDO T. FESTEJO/ NORIEL L. PLAZA

Sheet 1.A. Loan Calculators(JACINTO)
A1: LEIMCO Loan Calculator
B4: Data of Loan | H4: Summary of Loan
C5: Loan Amount | D5: 20000 | G5: 24 | I5: Payment per Schedule | J5: =ABS(PMT(Interest_Rate/Num_Pmt_Per_Year,Loan_Years*Num_Pmt_Per_Year,Loan_Amount)) -> 3570.5162
C6: Annual interest rate | D6: 0.12 | I6: Scheduled number of payments | J6: =Num_Pmt_Per_Year -> 6
C7: Loan Period (Years) | D7: 1 | I7: Actual number of payments | J7: =J6 -> 6
C8: Number of payments per year | D8: 6 | I8: Total early payments | J8: 0
C9: Loan Granted | D9: =+TODAY() -> 46266 | I9: Total interest | J9: =SUM(Int) -> 1423.0975
C10: Optional Extra Payments (Optional)
B11: Name of Borrower : | C11: **JACINTO, EUFEMIO JOSE N.** | I11: Actual Interest Rate per Annum: | J11: =+J9/Loan_Amount -> 0.071154874
A15: Pmt. No. | B15: Payment Date | C15: Beginning Balance | D15: Scheduled Payment | E15: Extra Payment | F15: Total Payment | G15: Principal | H15: Interest | I15: Ending Balance | J15: Cumulative Interest
A17: 1 | B17: =VLOOKUP(A17,#REF!,2,0) -> #REF! | C17: =Loan_Amount -> 20000 | D17: =ABS(PMT(Interest_Rate/Num_Pmt_Per_Year,Loan_Years*Num_Pmt_Per_Year,Loan_Amount)) -> 3570.5162 | E17: =IF(AND(Pay_Num<>"",Sched_Pay+Scheduled_Extra_Payments<Beg_Bal),Scheduled_Extra_Payments,IF(AND(Pay_Num<>"",Beg_Bal-Sched_Pay>0),Beg_Bal-Sched_Pay,IF(Pay_Num<>"",0,""))) -> 0 | F17: =IF(AND(Pay_Num<>"",Sched_Pay+Extra_Pay<Beg_Bal),Sched_Pay+Extra_Pay,IF(Pay_Num<>"",Beg_Bal,"")) -> 3570.5162 | G17: =IF(Pay_Num<>"",Total_Pay-Int,"") -> 3170.5162 | H17: =IF(Pay_Num<>"",Beg_Bal*(Interest_Rate/Num_Pmt_Per_Year),"") -> 400 | I17: =IF(AND(Pay_Num<>"",Sched_Pay+Extra_Pay<Beg_Bal),Beg_Bal-Princ,IF(Pay_Num<>"",0,"")) -> 16829.484 | J17: =SUM($H$17:$H17) -> 400
A18: 2 | B18: =VLOOKUP(A18,#REF!,2,0) -> #REF! | C18: =IF(Pay_Num<>"",I17,"") -> 16829.484 | D18: =ABS(PMT(Interest_Rate/Num_Pmt_Per_Year,Loan_Years*Num_Pmt_Per_Year,Loan_Amount)) -> 3570.5162 | E18: =IF(AND(Pay_Num<>"",Sched_Pay+Scheduled_Extra_Payments<Beg_Bal),Scheduled_Extra_Payments,IF(AND(Pay_Num<>"",Beg_Bal-Sched_Pay>0),Beg_Bal-Sched_Pay,IF(Pay_Num<>"",0,""))) -> 0 | F18: =IF(AND(Pay_Num<>"",Sched_Pay+Extra_Pay<Beg_Bal),Sched_Pay+Extra_Pay,IF(Pay_Num<>"",Beg_Bal,"")) -> 3570.5162 | G18: =IF(Pay_Num<>"",Total_Pay-Int,"") -> 3233.9266 | H18: =IF(Pay_Num<>"",Beg_Bal*Interest_Rate/Num_Pmt_Per_Year,"") -> 336.58968 | I18: =IF(AND(Pay_Num<>"",Sched_Pay+Extra_Pay<Beg_Bal),Beg_Bal-Princ,IF(Pay_Num<>"",0,"")) -> 13595.557 | J18: =SUM($H$17:$H18) -> 736.58968
A19: 3 | B19: =VLOOKUP(A19,#REF!,2,0) -> #REF! | C19: =IF(Pay_Num<>"",I18,"") -> 13595.557 | D19: =ABS(PMT(Interest_Rate/Num_Pmt_Per_Year,Loan_Years*Num_Pmt_Per_Year,Loan_Amount)) -> 3570.5162 | E19: =IF(AND(Pay_Num<>"",Sched_Pay+Scheduled_Extra_Payments<Beg_Bal),Scheduled_Extra_Payments,IF(AND(Pay_Num<>"",Beg_Bal-Sched_Pay>0),Beg_Bal-Sched_Pay,IF(Pay_Num<>"",0,""))) -> 0 | F19: =IF(AND(Pay_Num<>"",Sched_Pay+Extra_Pay<Beg_Bal),Sched_Pay+Extra_Pay,IF(Pay_Num<>"",Beg_Bal,"")) -> 3570.5162 | G19: =IF(Pay_Num<>"",Total_Pay-Int,"") -> 3298.6051 | H19: =IF(Pay_Num<>"",Beg_Bal*Interest_Rate/Num_Pmt_Per_Year,"") -> 271.91114 | I19: =IF(AND(Pay_Num<>"",Sched_Pay+Extra_Pay<Beg_Bal),Beg_Bal-Princ,IF(Pay_Num<>"",0,"")) -> 10296.952 | J19: =SUM($H$17:$H19) -> 1008.5008
A20: 4 | B20: =VLOOKUP(A20,#REF!,2,0) -> #REF! | C20: =IF(Pay_Num<>"",I19,"") -> 10296.952 | D20: =ABS(PMT(Interest_Rate/Num_Pmt_Per_Year,Loan_Years*Num_Pmt_Per_Year,Loan_Amount)) -> 3570.5162 | E20: =IF(AND(Pay_Num<>"",Sched_Pay+Scheduled_Extra_Payments<Beg_Bal),Scheduled_Extra_Payments,IF(AND(Pay_Num<>"",Beg_Bal-Sched_Pay>0),Beg_Bal-Sched_Pay,IF(Pay_Num<>"",0,""))) -> 0 | F20: =IF(AND(Pay_Num<>"",Sched_Pay+Extra_Pay<Beg_Bal),Sched_Pay+Extra_Pay,IF(Pay_Num<>"",Beg_Bal,"")) -> 3570.5162 | G20: =IF(Pay_Num<>"",Total_Pay-Int,"") -> 3364.5772 | H20: =IF(Pay_Num<>"",Beg_Bal*Interest_Rate/Num_Pmt_Per_Year,"") -> 205.93904 | I20: =IF(AND(Pay_Num<>"",Sched_Pay+Extra_Pay<Beg_Bal),Beg_Bal-Princ,IF(Pay_Num<>"",0,"")) -> 6932.3749 | J20: =SUM($H$17:$H20) -> 1214.4399
A21: 5 | B21: =VLOOKUP(A21,#REF!,2,0) -> #REF! | C21: =IF(Pay_Num<>"",I20,"") -> 6932.3749 | D21: =ABS(PMT(Interest_Rate/Num_Pmt_Per_Year,Loan_Years*Num_Pmt_Per_Year,Loan_Amount)) -> 3570.5162 | E21: =IF(AND(Pay_Num<>"",Sched_Pay+Scheduled_Extra_Payments<Beg_Bal),Scheduled_Extra_Payments,IF(AND(Pay_Num<>"",Beg_Bal-Sched_Pay>0),Beg_Bal-Sched_Pay,IF(Pay_Num<>"",0,""))) -> 0 | F21: =IF(AND(Pay_Num<>"",Sched_Pay+Extra_Pay<Beg_Bal),Sched_Pay+Extra_Pay,IF(Pay_Num<>"",Beg_Bal,"")) -> 3570.5162 | G21: =IF(Pay_Num<>"",Total_Pay-Int,"") -> 3431.8687 | H21: =IF(Pay_Num<>"",Beg_Bal*Interest_Rate/Num_Pmt_Per_Year,"") -> 138.6475 | I21: =IF(AND(Pay_Num<>"",Sched_Pay+Extra_Pay<Beg_Bal),Beg_Bal-Princ,IF(Pay_Num<>"",0,"")) -> 3500.5061 | J21: =SUM($H$17:$H21) -> 1353.0874
A22: 6 | B22: =VLOOKUP(A22,#REF!,2,0) -> #REF! | C22: =IF(Pay_Num<>"",I21,"") -> 3500.5061 | D22: =ABS(PMT(Interest_Rate/Num_Pmt_Per_Year,Loan_Years*Num_Pmt_Per_Year,Loan_Amount)) -> 3570.5162 | E22: =IF(AND(Pay_Num<>"",Sched_Pay+Scheduled_Extra_Payments<Beg_Bal),Scheduled_Extra_Payments,IF(AND(Pay_Num<>"",Beg_Bal-Sched_Pay>0),Beg_Bal-Sched_Pay,IF(Pay_Num<>"",0,""))) -> 0 | F22: =IF(AND(Pay_Num<>"",Sched_Pay+Extra_Pay<Beg_Bal),Sched_Pay+Extra_Pay,IF(Pay_Num<>"",Beg_Bal,"")) -> 3500.5061 | G22: =IF(Pay_Num<>"",Total_Pay-Int,"") -> 3430.496 | H22: =IF(Pay_Num<>"",Beg_Bal*Interest_Rate/Num_Pmt_Per_Year,"") -> 70.010122 | I22: =IF(AND(Pay_Num<>"",Sched_Pay+Extra_Pay<Beg_Bal),Beg_Bal-Princ,IF(Pay_Num<>"",0,"")) -> 0 | J22: =SUM($H$17:$H22) -> 1423.0975
A23: 7 | B23: =VLOOKUP(A23,#REF!,2,0) -> #REF! | C23: =IF(Pay_Num<>"",I22,"") -> 0 | D23: =ABS(PMT(Interest_Rate/Num_Pmt_Per_Year,Loan_Years*Num_Pmt_Per_Year,Loan_Amount)) -> 3570.5162 | E23: =IF(AND(Pay_Num<>"",Sched_Pay+Scheduled_Extra_Payments<Beg_Bal),Scheduled_Extra_Payments,IF(AND(Pay_Num<>"",Beg_Bal-Sched_Pay>0),Beg_Bal-Sched_Pay,IF(Pay_Num<>"",0,""))) -> 0 | F23: =IF(AND(Pay_Num<>"",Sched_Pay+Extra_Pay<Beg_Bal),Sched_Pay+Extra_Pay,IF(Pay_Num<>"",Beg_Bal,"")) -> 0 | G23: =IF(Pay_Num<>"",Total_Pay-Int,"") -> 0 | H23: =IF(Pay_Num<>"",Beg_Bal*Interest_Rate/Num_Pmt_Per_Year,"") -> 0 | I23: =IF(AND(Pay_Num<>"",Sched_Pay+Extra_Pay<Beg_Bal),Beg_Bal-Princ,IF(Pay_Num<>"",0,"")) -> 0 | J23: =SUM($H$17:$H23) -> 1423.0975
A24: 8 | B24: =VLOOKUP(A24,#REF!,2,0) -> #REF! | C24: =IF(Pay_Num<>"",I23,"") -> 0 | D24: =ABS(PMT(Interest_Rate/Num_Pmt_Per_Year,Loan_Years*Num_Pmt_Per_Year,Loan_Amount)) -> 3570.5162 | E24: =IF(AND(Pay_Num<>"",Sched_Pay+Scheduled_Extra_Payments<Beg_Bal),Scheduled_Extra_Payments,IF(AND(Pay_Num<>"",Beg_Bal-Sched_Pay>0),Beg_Bal-Sched_Pay,IF(Pay_Num<>"",0,""))) -> 0 | F24: =IF(AND(Pay_Num<>"",Sched_Pay+Extra_Pay<Beg_Bal),Sched_Pay+Extra_Pay,IF(Pay_Num<>"",Beg_Bal,"")) -> 0 | G24: =IF(Pay_Num<>"",Total_Pay-Int,"") -> 0 | H24: =IF(Pay_Num<>"",Beg_Bal*Interest_Rate/Num_Pmt_Per_Year,"") -> 0 | I24: =IF(AND(Pay_Num<>"",Sched_Pay+Extra_Pay<Beg_Bal),Beg_Bal-Princ,IF(Pay_Num<>"",0,"")) -> 0 | J24: =SUM($H$17:$H24) -> 1423.0975
A25: 9 | B25: =VLOOKUP(A25,#REF!,2,0) -> #REF! | C25: =IF(Pay_Num<>"",I24,"") -> 0 | D25: =ABS(PMT(Interest_Rate/Num_Pmt_Per_Year,Loan_Years*Num_Pmt_Per_Year,Loan_Amount)) -> 3570.5162 | E25: =IF(AND(Pay_Num<>"",Sched_Pay+Scheduled_Extra_Payments<Beg_Bal),Scheduled_Extra_Payments,IF(AND(Pay_Num<>"",Beg_Bal-Sched_Pay>0),Beg_Bal-Sched_Pay,IF(Pay_Num<>"",0,""))) -> 0 | F25: =IF(AND(Pay_Num<>"",Sched_Pay+Extra_Pay<Beg_Bal),Sched_Pay+Extra_Pay,IF(Pay_Num<>"",Beg_Bal,"")) -> 0 | G25: =IF(Pay_Num<>"",Total_Pay-Int,"") -> 0 | H25: =IF(Pay_Num<>"",Beg_Bal*Interest_Rate/Num_Pmt_Per_Year,"") -> 0 | I25: =IF(AND(Pay_Num<>"",Sched_Pay+Extra_Pay<Beg_Bal),Beg_Bal-Princ,IF(Pay_Num<>"",0,"")) -> 0 | J25: =SUM($H$17:$H25) -> 1423.0975
A26: 10 | B26: =VLOOKUP(A26,#REF!,2,0) -> #REF! | C26: =IF(Pay_Num<>"",I25,"") -> 0 | D26: =ABS(PMT(Interest_Rate/Num_Pmt_Per_Year,Loan_Years*Num_Pmt_Per_Year,Loan_Amount)) -> 3570.5162 | E26: =IF(AND(Pay_Num<>"",Sched_Pay+Scheduled_Extra_Payments<Beg_Bal),Scheduled_Extra_Payments,IF(AND(Pay_Num<>"",Beg_Bal-Sched_Pay>0),Beg_Bal-Sched_Pay,IF(Pay_Num<>"",0,""))) -> 0 | F26: =IF(AND(Pay_Num<>"",Sched_Pay+Extra_Pay<Beg_Bal),Sched_Pay+Extra_Pay,IF(Pay_Num<>"",Beg_Bal,"")) -> 0 | G26: =IF(Pay_Num<>"",Total_Pay-Int,"") -> 0 | H26: =IF(Pay_Num<>"",Beg_Bal*Interest_Rate/Num_Pmt_Per_Year,"") -> 0 | I26: =IF(AND(Pay_Num<>"",Sched_Pay+Extra_Pay<Beg_Bal),Beg_Bal-Princ,IF(Pay_Num<>"",0,"")) -> 0 | J26: =SUM($H$17:$H26) -> 1423.0975
A27: 11 | B27: =VLOOKUP(A27,#REF!,2,0) -> #REF! | C27: =IF(Pay_Num<>"",I26,"") -> 0 | D27: =ABS(PMT(Interest_Rate/Num_Pmt_Per_Year,Loan_Years*Num_Pmt_Per_Year,Loan_Amount)) -> 3570.5162 | E27: =IF(AND(Pay_Num<>"",Sched_Pay+Scheduled_Extra_Payments<Beg_Bal),Scheduled_Extra_Payments,IF(AND(Pay_Num<>"",Beg_Bal-Sched_Pay>0),Beg_Bal-Sched_Pay,IF(Pay_Num<>"",0,""))) -> 0 | F27: =IF(AND(Pay_Num<>"",Sched_Pay+Extra_Pay<Beg_Bal),Sched_Pay+Extra_Pay,IF(Pay_Num<>"",Beg_Bal,"")) -> 0 | G27: =IF(Pay_Num<>"",Total_Pay-Int,"") -> 0 | H27: =IF(Pay_Num<>"",Beg_Bal*Interest_Rate/Num_Pmt_Per_Year,"") -> 0 | I27: =IF(AND(Pay_Num<>"",Sched_Pay+Extra_Pay<Beg_Bal),Beg_Bal-Princ,IF(Pay_Num<>"",0,"")) -> 0 | J27: =SUM($H$17:$H27) -> 1423.0975
A28: 12 | B28: =VLOOKUP(A28,#REF!,2,0) -> #REF! | C28: =IF(Pay_Num<>"",I27,"") -> 0 | D28: =ABS(PMT(Interest_Rate/Num_Pmt_Per_Year,Loan_Years*Num_Pmt_Per_Year,Loan_Amount)) -> 3570.5162 | E28: =IF(AND(Pay_Num<>"",Sched_Pay+Scheduled_Extra_Payments<Beg_Bal),Scheduled_Extra_Payments,IF(AND(Pay_Num<>"",Beg_Bal-Sched_Pay>0),Beg_Bal-Sched_Pay,IF(Pay_Num<>"",0,""))) -> 0 | F28: =IF(AND(Pay_Num<>"",Sched_Pay+Extra_Pay<Beg_Bal),Sched_Pay+Extra_Pay,IF(Pay_Num<>"",Beg_Bal,"")) -> 0 | G28: =IF(Pay_Num<>"",Total_Pay-Int,"") -> 0 | H28: =IF(Pay_Num<>"",Beg_Bal*Interest_Rate/Num_Pmt_Per_Year,"") -> 0 | I28: =IF(AND(Pay_Num<>"",Sched_Pay+Extra_Pay<Beg_Bal),Beg_Bal-Princ,IF(Pay_Num<>"",0,"")) -> 0 | J28: =SUM($H$17:$H28) -> 1423.0975
A29: 13 | B29: =VLOOKUP(A29,#REF!,2,0) -> #REF! | C29: =IF(Pay_Num<>"",I28,"") -> 0 | D29: =ABS(PMT(Interest_Rate/Num_Pmt_Per_Year,Loan_Years*Num_Pmt_Per_Year,Loan_Amount)) -> 3570.5162 | E29: =IF(AND(Pay_Num<>"",Sched_Pay+Scheduled_Extra_Payments<Beg_Bal),Scheduled_Extra_Payments,IF(AND(Pay_Num<>"",Beg_Bal-Sched_Pay>0),Beg_Bal-Sched_Pay,IF(Pay_Num<>"",0,""))) -> 0 | F29: =IF(AND(Pay_Num<>"",Sched_Pay+Extra_Pay<Beg_Bal),Sched_Pay+Extra_Pay,IF(Pay_Num<>"",Beg_Bal,"")) -> 0 | G29: =IF(Pay_Num<>"",Total_Pay-Int,"") -> 0 | H29: =IF(Pay_Num<>"",Beg_Bal*Interest_Rate/Num_Pmt_Per_Year,"") -> 0 | I29: =IF(AND(Pay_Num<>"",Sched_Pay+Extra_Pay<Beg_Bal),Beg_Bal-Princ,IF(Pay_Num<>"",0,"")) -> 0 | J29: =SUM($H$17:$H29) -> 1423.0975
... A40: 24 | B40: =VLOOKUP(A40,#REF!,2,0) -> #REF! | C40: =IF(Pay_Num<>"",I39,"") -> 0 | D40: =ABS(PMT(Interest_Rate/Num_Pmt_Per_Year,Loan_Years*Num_Pmt_Per_Year,Loan_Amount)) -> 3570.5162 | E40: =IF(AND(Pay_Num<>"",Sched_Pay+Scheduled_Extra_Payments<Beg_Bal),Scheduled_Extra_Payments,IF(AND(Pay_Num<>"",Beg_Bal-Sched_Pay>0),Beg_Bal-Sched_Pay,IF(Pay_Num<>"",0,""))) -> 0 | F40: =IF(AND(Pay_Num<>"",Sched_Pay+Extra_Pay<Beg_Bal),Sched_Pay+Extra_Pay,IF(Pay_Num<>"",Beg_Bal,"")) -> 0 | G40: =IF(Pay_Num<>"",Total_Pay-Int,"") -> 0 | H40: =IF(Pay_Num<>"",Beg_Bal*Interest_Rate/Num_Pmt_Per_Year,"") -> 0 | I40: =IF(AND(Pay_Num<>"",Sched_Pay+Extra_Pay<Beg_Bal),Beg_Bal-Princ,IF(Pay_Num<>"",0,"")) -> 0 | J40: =SUM($H$17:$H40) -> 1423.0975
A41: 25 | B41: =VLOOKUP(A41,#REF!,2,0) -> #REF! | C41: =IF(Pay_Num<>"",I40,"") -> 0 | D41: =IF(Pay_Num<>"",Scheduled_Monthly_Payment,"") -> 3570.5162 | E41: =IF(AND(Pay_Num<>"",Sched_Pay+Scheduled_Extra_Payments<Beg_Bal),Scheduled_Extra_Payments,IF(AND(Pay_Num<>"",Beg_Bal-Sched_Pay>0),Beg_Bal-Sched_Pay,IF(Pay_Num<>"",0,""))) -> 0 | F41: =IF(AND(Pay_Num<>"",Sched_Pay+Extra_Pay<Beg_Bal),Sched_Pay+Extra_Pay,IF(Pay_Num<>"",Beg_Bal,"")) -> 0 | G41: =IF(Pay_Num<>"",Total_Pay-Int,"") -> 0 | H41: =IF(Pay_Num<>"",Beg_Bal*Interest_Rate/Num_Pmt_Per_Year,"") -> 0 | I41: =IF(AND(Pay_Num<>"",Sched_Pay+Extra_Pay<Beg_Bal),Beg_Bal-Princ,IF(Pay_Num<>"",0,"")) -> 0 | J41: =SUM($H$17:$H41) -> 1423.0975
A42: 26 | B42: =VLOOKUP(A42,#REF!,2,0) -> #REF! | C42: =IF(Pay_Num<>"",I41,"") -> 0 | D42: =IF(Pay_Num<>"",Scheduled_Monthly_Payment,"") -> 3570.5162 | E42: =IF(AND(Pay_Num<>"",Sched_Pay+Scheduled_Extra_Payments<Beg_Bal),Scheduled_Extra_Payments,IF(AND(Pay_Num<>"",Beg_Bal-Sched_Pay>0),Beg_Bal-Sched_Pay,IF(Pay_Num<>"",0,""))) -> 0 | F42: =IF(AND(Pay_Num<>"",Sched_Pay+Extra_Pay<Beg_Bal),Sched_Pay+Extra_Pay,IF(Pay_Num<>"",Beg_Bal,"")) -> 0 | G42: =IF(Pay_Num<>"",Total_Pay-Int,"") -> 0 | H42: =IF(Pay_Num<>"",Beg_Bal*Interest_Rate/Num_Pmt_Per_Year,"") -> 0 | I42: =IF(AND(Pay_Num<>"",Sched_Pay+Extra_Pay<Beg_Bal),Beg_Bal-Princ,IF(Pay_Num<>"",0,"")) -> 0 | J42: =SUM($H$17:$H42) -> 1423.0975
A43: 27 | B43: =VLOOKUP(A43,#REF!,2,0) -> #REF! | C43: =IF(Pay_Num<>"",I42,"") -> 0 | D43: =IF(Pay_Num<>"",Scheduled_Monthly_Payment,"") -> 3570.5162 | E43: =IF(AND(Pay_Num<>"",Sched_Pay+Scheduled_Extra_Payments<Beg_Bal),Scheduled_Extra_Payments,IF(AND(Pay_Num<>"",Beg_Bal-Sched_Pay>0),Beg_Bal-Sched_Pay,IF(Pay_Num<>"",0,""))) -> 0 | F43: =IF(AND(Pay_Num<>"",Sched_Pay+Extra_Pay<Beg_Bal),Sched_Pay+Extra_Pay,IF(Pay_Num<>"",Beg_Bal,"")) -> 0 | G43: =IF(Pay_Num<>"",Total_Pay-Int,"") -> 0 | H43: =IF(Pay_Num<>"",Beg_Bal*Interest_Rate/Num_Pmt_Per_Year,"") -> 0 | I43: =IF(AND(Pay_Num<>"",Sched_Pay+Extra_Pay<Beg_Bal),Beg_Bal-Princ,IF(Pay_Num<>"",0,"")) -> 0 | J43: =SUM($H$17:$H43) -> 1423.0975
A44: 28 | B44: =VLOOKUP(A44,#REF!,2,0) -> #REF! | C44: =IF(Pay_Num<>"",I43,"") -> 0 | D44: =IF(Pay_Num<>"",Scheduled_Monthly_Payment,"") -> 3570.5162 | E44: =IF(AND(Pay_Num<>"",Sched_Pay+Scheduled_Extra_Payments<Beg_Bal),Scheduled_Extra_Payments,IF(AND(Pay_Num<>"",Beg_Bal-Sched_Pay>0),Beg_Bal-Sched_Pay,IF(Pay_Num<>"",0,""))) -> 0 | F44: =IF(AND(Pay_Num<>"",Sched_Pay+Extra_Pay<Beg_Bal),Sched_Pay+Extra_Pay,IF(Pay_Num<>"",Beg_Bal,"")) -> 0 | G44: =IF(Pay_Num<>"",Total_Pay-Int,"") -> 0 | H44: =IF(Pay_Num<>"",Beg_Bal*Interest_Rate/Num_Pmt_Per_Year,"") -> 0 | I44: =IF(AND(Pay_Num<>"",Sched_Pay+Extra_Pay<Beg_Bal),Beg_Bal-Princ,IF(Pay_Num<>"",0,"")) -> 0 | J44: =SUM($H$17:$H44) -> 1423.0975
A45: 29 | B45: =VLOOKUP(A45,#REF!,2,0) -> #REF! | C45: =IF(Pay_Num<>"",I44,"") -> 0 | D45: =IF(Pay_Num<>"",Scheduled_Monthly_Payment,"") -> 3570.5162 | E45: =IF(AND(Pay_Num<>"",Sched_Pay+Scheduled_Extra_Payments<Beg_Bal),Scheduled_Extra_Payments,IF(AND(Pay_Num<>"",Beg_Bal-Sched_Pay>0),Beg_Bal-Sched_Pay,IF(Pay_Num<>"",0,""))) -> 0 | F45: =IF(AND(Pay_Num<>"",Sched_Pay+Extra_Pay<Beg_Bal),Sched_Pay+Extra_Pay,IF(Pay_Num<>"",Beg_Bal,"")) -> 0 | G45: =IF(Pay_Num<>"",Total_Pay-Int,"") -> 0 | H45: =IF(Pay_Num<>"",Beg_Bal*Interest_Rate/Num_Pmt_Per_Year,"") -> 0 | I45: =IF(AND(Pay_Num<>"",Sched_Pay+Extra_Pay<Beg_Bal),Beg_Bal-Princ,IF(Pay_Num<>"",0,"")) -> 0 | J45: =SUM($H$17:$H45) -> 1423.0975
A46: 30 | B46: =VLOOKUP(A46,#REF!,2,0) -> #REF! | C46: =IF(Pay_Num<>"",I45,"") -> 0 | D46: =IF(Pay_Num<>"",Scheduled_Monthly_Payment,"") -> 3570.5162 | E46: =IF(AND(Pay_Num<>"",Sched_Pay+Scheduled_Extra_Payments<Beg_Bal),Scheduled_Extra_Payments,IF(AND(Pay_Num<>"",Beg_Bal-Sched_Pay>0),Beg_Bal-Sched_Pay,IF(Pay_Num<>"",0,""))) -> 0 | F46: =IF(AND(Pay_Num<>"",Sched_Pay+Extra_Pay<Beg_Bal),Sched_Pay+Extra_Pay,IF(Pay_Num<>"",Beg_Bal,"")) -> 0 | G46: =IF(Pay_Num<>"",Total_Pay-Int,"") -> 0 | H46: =IF(Pay_Num<>"",Beg_Bal*Interest_Rate/Num_Pmt_Per_Year,"") -> 0 | I46: =IF(AND(Pay_Num<>"",Sched_Pay+Extra_Pay<Beg_Bal),Beg_Bal-Princ,IF(Pay_Num<>"",0,"")) -> 0 | J46: =SUM($H$17:$H46) -> 1423.0975
A47: 31 | B47: =VLOOKUP(A47,#REF!,2,0) -> #REF! | C47: =IF(Pay_Num<>"",I46,"") -> 0 | D47: =IF(Pay_Num<>"",Scheduled_Monthly_Payment,"") -> 3570.5162 | E47: =IF(AND(Pay_Num<>"",Sched_Pay+Scheduled_Extra_Payments<Beg_Bal),Scheduled_Extra_Payments,IF(AND(Pay_Num<>"",Beg_Bal-Sched_Pay>0),Beg_Bal-Sched_Pay,IF(Pay_Num<>"",0,""))) -> 0 | F47: =IF(AND(Pay_Num<>"",Sched_Pay+Extra_Pay<Beg_Bal),Sched_Pay+Extra_Pay,IF(Pay_Num<>"",Beg_Bal,"")) -> 0 | G47: =IF(Pay_Num<>"",Total_Pay-Int,"") -> 0 | H47: =IF(Pay_Num<>"",Beg_Bal*Interest_Rate/Num_Pmt_Per_Year,"") -> 0 | I47: =IF(AND(Pay_Num<>"",Sched_Pay+Extra_Pay<Beg_Bal),Beg_Bal-Princ,IF(Pay_Num<>"",0,"")) -> 0 | J47: =SUM($H$17:$H47) -> 1423.0975
A48: 32 | B48: =VLOOKUP(A48,#REF!,2,0) -> #REF! | C48: =IF(Pay_Num<>"",I47,"") -> 0 | D48: =IF(Pay_Num<>"",Scheduled_Monthly_Payment,"") -> 3570.5162 | E48: =IF(AND(Pay_Num<>"",Sched_Pay+Scheduled_Extra_Payments<Beg_Bal),Scheduled_Extra_Payments,IF(AND(Pay_Num<>"",Beg_Bal-Sched_Pay>0),Beg_Bal-Sched_Pay,IF(Pay_Num<>"",0,""))) -> 0 | F48: =IF(AND(Pay_Num<>"",Sched_Pay+Extra_Pay<Beg_Bal),Sched_Pay+Extra_Pay,IF(Pay_Num<>"",Beg_Bal,"")) -> 0 | G48: =IF(Pay_Num<>"",Total_Pay-Int,"") -> 0 | H48: =IF(Pay_Num<>"",Beg_Bal*Interest_Rate/Num_Pmt_Per_Year,"") -> 0 | I48: =IF(AND(Pay_Num<>"",Sched_Pay+Extra_Pay<Beg_Bal),Beg_Bal-Princ,IF(Pay_Num<>"",0,"")) -> 0 | J48: =SUM($H$17:$H48) -> 1423.0975
A49: 33 | B49: =VLOOKUP(A49,#REF!,2,0) -> #REF! | C49: =IF(Pay_Num<>"",I48,"") -> 0 | D49: =IF(Pay_Num<>"",Scheduled_Monthly_Payment,"") -> 3570.5162 | E49: =IF(AND(Pay_Num<>"",Sched_Pay+Scheduled_Extra_Payments<Beg_Bal),Scheduled_Extra_Payments,IF(AND(Pay_Num<>"",Beg_Bal-Sched_Pay>0),Beg_Bal-Sched_Pay,IF(Pay_Num<>"",0,""))) -> 0 | F49: =IF(AND(Pay_Num<>"",Sched_Pay+Extra_Pay<Beg_Bal),Sched_Pay+Extra_Pay,IF(Pay_Num<>"",Beg_Bal,"")) -> 0 | G49: =IF(Pay_Num<>"",Total_Pay-Int,"") -> 0 | H49: =IF(Pay_Num<>"",Beg_Bal*Interest_Rate/Num_Pmt_Per_Year,"") -> 0 | I49: =IF(AND(Pay_Num<>"",Sched_Pay+Extra_Pay<Beg_Bal),Beg_Bal-Princ,IF(Pay_Num<>"",0,"")) -> 0 | J49: =SUM($H$17:$H49) -> 1423.0975
A50: 34 | B50: =VLOOKUP(A50,#REF!,2,0) -> #REF! | C50: =IF(Pay_Num<>"",I49,"") -> 0 | D50: =IF(Pay_Num<>"",Scheduled_Monthly_Payment,"") -> 3570.5162 | E50: =IF(AND(Pay_Num<>"",Sched_Pay+Scheduled_Extra_Payments<Beg_Bal),Scheduled_Extra_Payments,IF(AND(Pay_Num<>"",Beg_Bal-Sched_Pay>0),Beg_Bal-Sched_Pay,IF(Pay_Num<>"",0,""))) -> 0 | F50: =IF(AND(Pay_Num<>"",Sched_Pay+Extra_Pay<Beg_Bal),Sched_Pay+Extra_Pay,IF(Pay_Num<>"",Beg_Bal,"")) -> 0 | G50: =IF(Pay_Num<>"",Total_Pay-Int,"") -> 0 | H50: =IF(Pay_Num<>"",Beg_Bal*Interest_Rate/Num_Pmt_Per_Year,"") -> 0 | I50: =IF(AND(Pay_Num<>"",Sched_Pay+Extra_Pay<Beg_Bal),Beg_Bal-Princ,IF(Pay_Num<>"",0,"")) -> 0 | J50: =SUM($H$17:$H50) -> 1423.0975
A51: 35 | B51: =VLOOKUP(A51,#REF!,2,0) -> #REF! | C51: =IF(Pay_Num<>"",I50,"") -> 0 | D51: =IF(Pay_Num<>"",Scheduled_Monthly_Payment,"") -> 3570.5162 | E51: =IF(AND(Pay_Num<>"",Sched_Pay+Scheduled_Extra_Payments<Beg_Bal),Scheduled_Extra_Payments,IF(AND(Pay_Num<>"",Beg_Bal-Sched_Pay>0),Beg_Bal-Sched_Pay,IF(Pay_Num<>"",0,""))) -> 0 | F51: =IF(AND(Pay_Num<>"",Sched_Pay+Extra_Pay<Beg_Bal),Sched_Pay+Extra_Pay,IF(Pay_Num<>"",Beg_Bal,"")) -> 0 | G51: =IF(Pay_Num<>"",Total_Pay-Int,"") -> 0 | H51: =IF(Pay_Num<>"",Beg_Bal*Interest_Rate/Num_Pmt_Per_Year,"") -> 0 | I51: =IF(AND(Pay_Num<>"",Sched_Pay+Extra_Pay<Beg_Bal),Beg_Bal-Princ,IF(Pay_Num<>"",0,"")) -> 0 | J51: =SUM($H$17:$H51) -> 1423.0975
A52: 36 | B52: =VLOOKUP(A52,#REF!,2,0) -> #REF! | C52: =IF(Pay_Num<>"",I51,"") -> 0 | D52: =IF(Pay_Num<>"",Scheduled_Monthly_Payment,"") -> 3570.5162 | E52: =IF(AND(Pay_Num<>"",Sched_Pay+Scheduled_Extra_Payments<Beg_Bal),Scheduled_Extra_Payments,IF(AND(Pay_Num<>"",Beg_Bal-Sched_Pay>0),Beg_Bal-Sched_Pay,IF(Pay_Num<>"",0,""))) -> 0 | F52: =IF(AND(Pay_Num<>"",Sched_Pay+Extra_Pay<Beg_Bal),Sched_Pay+Extra_Pay,IF(Pay_Num<>"",Beg_Bal,"")) -> 0 | G52: =IF(Pay_Num<>"",Total_Pay-Int,"") -> 0 | H52: =IF(Pay_Num<>"",Beg_Bal*Interest_Rate/Num_Pmt_Per_Year,"") -> 0 | I52: =IF(AND(Pay_Num<>"",Sched_Pay+Extra_Pay<Beg_Bal),Beg_Bal-Princ,IF(Pay_Num<>"",0,"")) -> 0 | J52: =SUM($H$17:$H52) -> 1423.0975
... A64: 48 | B64: =VLOOKUP(A64,#REF!,2,0) -> #REF! | C64: =IF(Pay_Num<>"",I63,"") -> 0 | D64: =IF(Pay_Num<>"",Scheduled_Monthly_Payment,"") -> 3570.5162 | E64: =IF(AND(Pay_Num<>"",Sched_Pay+Scheduled_Extra_Payments<Beg_Bal),Scheduled_Extra_Payments,IF(AND(Pay_Num<>"",Beg_Bal-Sched_Pay>0),Beg_Bal-Sched_Pay,IF(Pay_Num<>"",0,""))) -> 0 | F64: =IF(AND(Pay_Num<>"",Sched_Pay+Extra_Pay<Beg_Bal),Sched_Pay+Extra_Pay,IF(Pay_Num<>"",Beg_Bal,"")) -> 0 | G64: =IF(Pay_Num<>"",Total_Pay-Int,"") -> 0 | H64: =IF(Pay_Num<>"",Beg_Bal*Interest_Rate/Num_Pmt_Per_Year,"") -> 0 | I64: =IF(AND(Pay_Num<>"",Sched_Pay+Extra_Pay<Beg_Bal),Beg_Bal-Princ,IF(Pay_Num<>"",0,"")) -> 0 | J64: =SUM($H$17:$H64) -> 1423.0975
A66: 49 | B66: =IF(Pay_Num<>"",DATE(YEAR(Loan_Start),MONTH(Loan_Start)+(Pay_Num)*12/Num_Pmt_Per_Year,DAY(Loan_Start)),"") -> 49249 | C66: =IF(Pay_Num<>"",I64,"") -> 0 | D66: =IF(Pay_Num<>"",Scheduled_Monthly_Payment,"") -> 3570.5162 | E66: =IF(AND(Pay_Num<>"",Sched_Pay+Scheduled_Extra_Payments<Beg_Bal),Scheduled_Extra_Payments,IF(AND(Pay_Num<>"",Beg_Bal-Sched_Pay>0),Beg_Bal-Sched_Pay,IF(Pay_Num<>"",0,""))) -> 0 | F66: =IF(AND(Pay_Num<>"",Sched_Pay+Extra_Pay<Beg_Bal),Sched_Pay+Extra_Pay,IF(Pay_Num<>"",Beg_Bal,"")) -> 0 | G66: =IF(Pay_Num<>"",Total_Pay-Int,"") -> 0 | H66: =IF(Pay_Num<>"",Beg_Bal*Interest_Rate/Num_Pmt_Per_Year,"") -> 0 | I66: =IF(AND(Pay_Num<>"",Sched_Pay+Extra_Pay<Beg_Bal),Beg_Bal-Princ,IF(Pay_Num<>"",0,"")) -> 0 | J66: =SUM($H$17:$H66) -> 1423.0975
A67: 50 | B67: =IF(Pay_Num<>"",DATE(YEAR(Loan_Start),MONTH(Loan_Start)+(Pay_Num)*12/Num_Pmt_Per_Year,DAY(Loan_Start)),"") -> 49310 | C67: =IF(Pay_Num<>"",I66,"") -> 0 | D67: =IF(Pay_Num<>"",Scheduled_Monthly_Payment,"") -> 3570.5162 | E67: =IF(AND(Pay_Num<>"",Sched_Pay+Scheduled_Extra_Payments<Beg_Bal),Scheduled_Extra_Payments,IF(AND(Pay_Num<>"",Beg_Bal-Sched_Pay>0),Beg_Bal-Sched_Pay,IF(Pay_Num<>"",0,""))) -> 0 | F67: =IF(AND(Pay_Num<>"",Sched_Pay+Extra_Pay<Beg_Bal),Sched_Pay+Extra_Pay,IF(Pay_Num<>"",Beg_Bal,"")) -> 0 | G67: =IF(Pay_Num<>"",Total_Pay-Int,"") -> 0 | H67: =IF(Pay_Num<>"",Beg_Bal*Interest_Rate/Num_Pmt_Per_Year,"") -> 0 | I67: =IF(AND(Pay_Num<>"",Sched_Pay+Extra_Pay<Beg_Bal),Beg_Bal-Princ,IF(Pay_Num<>"",0,"")) -> 0 | J67: =SUM($H$17:$H67) -> 1423.0975
A68: 51 | B68: =IF(Pay_Num<>"",DATE(YEAR(Loan_Start),MONTH(Loan_Start)+(Pay_Num)*12/Num_Pmt_Per_Year,DAY(Loan_Start)),"") -> 49369 | C68: =IF(Pay_Num<>"",I67,"") -> 0 | D68: =IF(Pay_Num<>"",Scheduled_Monthly_Payment,"") -> 3570.5162 | E68: =IF(AND(Pay_Num<>"",Sched_Pay+Scheduled_Extra_Payments<Beg_Bal),Scheduled_Extra_Payments,IF(AND(Pay_Num<>"",Beg_Bal-Sched_Pay>0),Beg_Bal-Sched_Pay,IF(Pay_Num<>"",0,""))) -> 0 | F68: =IF(AND(Pay_Num<>"",Sched_Pay+Extra_Pay<Beg_Bal),Sched_Pay+Extra_Pay,IF(Pay_Num<>"",Beg_Bal,"")) -> 0 | G68: =IF(Pay_Num<>"",Total_Pay-Int,"") -> 0 | H68: =IF(Pay_Num<>"",Beg_Bal*Interest_Rate/Num_Pmt_Per_Year,"") -> 0 | I68: =IF(AND(Pay_Num<>"",Sched_Pay+Extra_Pay<Beg_Bal),Beg_Bal-Princ,IF(Pay_Num<>"",0,"")) -> 0 | J68: =SUM($H$17:$H68) -> 1423.0975
...

Sheet 1.B. Loan-JACINTO
C2: ='1.A. Loan Calculators(JACINTO)'!C11 -> **JACINTO, EUFEMIO JOSE N.**
B3: Payee: | F3: Amount : | G3: =+G25 -> -38634.603
C5: **SIXTY SIX THOUSAND THREE HUNDRED SIXTY FIVE & 40/100 ONLY**
B6: Amount in Words:
B10: Account Code | C10: Account Title | F10: Debit | G10: Credit
C21: A/R - Loans | F21: =SUM(G22:G25) -> 21423.097
D22: Other Income - Miscellaneous | G22: 200
D23: A/R - Tsukiden | G23: 58434.603
D24: Interest Income - Loans | G24: ='1.A. Loan Calculators(JACINTO)'!J9 -> 1423.0975
D25: Cash in Bank - RCBC S/A | G25: =+D40-G23-G22 -> -38634.603
B35: Total Debits/Credits | F35: =SUM(F11:F34) -> 21423.097 | G35: =SUM(G11:G34) -> 21423.097
B38: PARTICULAR:
C40: Loan Amount | D40: ='1.A. Loan Calculators(JACINTO)'!Loan_Amount -> 20000
C41: Number of payments per year | D41: ='1.A. Loan Calculators(JACINTO)'!Num_Pmt_Per_Year -> 6
C42: Annual interest rate | D42: ='1.A. Loan Calculators(JACINTO)'!Interest_Rate -> 0.12
C43: Payment per Schedule | D43: ='1.A. Loan Calculators(JACINTO)'!Scheduled_Monthly_Payment -> 3570.5162 | F43: (per cut-off)
D44: =+D43*2 -> 7141.0325 | F44: (per month)
B53: Prepared By: | C53: D. REMETIO | E53: Received By: | F53: =+C2 -> **JACINTO, EUFEMIO JOSE N.**
B57: Approved By: | C57: JETF / NLP / ECF | E57: Received Date:
C61: Check Number: | F61: Check Voucher Date: | G61: =+TODAY() -> 46266
G62: =+NOW() -> 46266.644
C66: =+C2 -> **JACINTO, EUFEMIO JOSE N.**
C67: =+C5 -> **SIXTY SIX THOUSAND THREE HUNDRED SIXTY FIVE & 40/100 ONLY**
C68: =+G3 -> -38634.603
C69: =VLOOKUP(C66,#REF!,2,0) -> #REF!

Sheet 1.C. FT (JACINTO)
C2: LAGUNA ELECTRONICS INC | D2: ='1.B. Loan-JACINTO'!C69 -> #REF! | E2: ='1.B. Loan-JACINTO'!C66 -> **JACINTO, EUFEMIO JOSE N.**
C3: MULTI-PURPOSE COOPERATIVE
A5: ='1.B. Loan-JACINTO'!C68 -> -38634.603 | D5: COOPERATIVE LOAN
A7: ='1.B. Loan-JACINTO'!C67 -> **SIXTY SIX THOUSAND THREE HUNDRED SIXTY FIVE & 40/100 ONLY**
A10: J.FESTEJO / N.PLAZA / E.FILARCA

Sheet 1. D Checks (JACINTO)
H3: =+TODAY() -> 46266
C5: ='1.B. Loan-JACINTO'!C66 -> **JACINTO, EUFEMIO JOSE N.** | F5: 20000 | H5: =+'1.B. Loan-JACINTO'!G3 -> -38634.603
B7: =+'1.B. Loan-JACINTO'!C67 -> **SIXTY SIX THOUSAND THREE HUNDRED SIXTY FIVE & 40/100 ONLY**

Sheet Summary (LOANS)
B2: SUMMARY DETAILS
B3: PAYEE | C3: REMARKS | D3: AMOUNT
B4: ='1.B. Loan-JACINTO'!C66 -> **JACINTO, EUFEMIO JOSE N.** | C4: COOPERATIVE LOAN (FUND TRANSFER) | D4: ='1.B. Loan-JACINTO'!C68 -> -38634.603
C18: TOTAL CHECK AMOUNT | D18: =SUM(D4:D13) -> -38634.603

Sheet RCBC Acct No. (2)
A1: ID No. | B1: Name | C1: Check Name | D1: RCBC Account No.
A2: 4226 | B2: SARMIENTO, SENEN M | C2: **SARMIENTO, SENEN M** | D2: 9024432055 | G2: 44206
A3: 329 | B3: ALCID, ALEXIA G | C3: **ALCID, ALEXIA G** | D3: 9024431563 | G3: 44221
A4: 359 | B4: ORBIGOSO, ROLLIE B | C4: **ORBIGOSO, ROLLIE B** | D4: 9024432160 | G4: 44237
A5: 6836 | B5: PLAZA, NORIEL L | C5: **PLAZA, NORIEL L** | D5: 9024431903 | G5: 44252
A6: 1990 | B6: YOSHIDA, KOJI | C6: **YOSHIDA, KOJI** | D6: 9024431148 | G6: 44265
A7: 1117 | B7: FILARCA JR., EULOGIO C | C7: **FILARCA JR., EULOGIO C** | D7: 9024432020 | G7: 44280
A8: 1493 | B8: LAMBIO, MAYLANIE G | C8: **LAMBIO, MAYLANIE G** | D8: 9024430990 | G8: 44296
A9: 6956 | B9: KOMATSU, KENJI . | C9: **KOMATSU, KENJI .** | D9: 9022259240 | G9: 44311
A10: 1442 | B10: EVANGELISTA, ROSALINDA P | C10: **EVANGELISTA, ROSALINDA P** | D10: 9024431326 | G10: 44326
A11: 2702 | B11: DIMLA, RAYMOND P | C11: **DIMLA, RAYMOND P** | D11: 9024430834 | G11: 44341
A12: 565 | B12: ORBIGOSO, JOSENIA B | C12: **ORBIGOSO, JOSENIA B** | D12: 9024431342 | G12: 44357
A13: 1438 | B13: ANTOLIN, ARNEL C | C13: **ANTOLIN, ARNEL C** | D13: 9024430885 | G13: 44372
... A106: 12053 | B106: JAVELOSA, ANDREA E. | C106: **JAVELOSA, ANDREA E.** | D106: 9024430982 | G106: 45787
A107: 64 | B107: ASIDERA, NELIA C. | C107: **ASIDERA, NELIA C.** | D107: 9024431016 | F107: 1 | G107: 45802
A108: 537 | B108: TOBIAS, CHERIL D. | C108: **TOBIAS, CHERIL D.** | D108: 9024431032 | F108: 2 | G108: 45818
A109: 7688 | B109: BARTOLOME, JOCELYN F. | C109: **BARTOLOME, JOCELYN F.** | D109: 9024431040 | F109: 3 | G109: 45833
A110: 256 | B110: VALERIO, LUISA O. | C110: **VALERIO, LUISA O.** | D110: 9024431075 | F110: 4 | G110: 45848
A111: 544 | B111: PALSIMON, CRISTINA D. | C111: **PALSIMON, CRISTINA D.** | D111: 9024431083 | F111: 5 | G111: 45863
A112: 14347 | B112: PASENCIA, ERLINIA C. | C112: **PASENCIA, ERLINIA C.** | D112: 9024431105 | F112: 6 | G112: 45879
A113: 14265 | B113: JAVIER, ELVIE D. | C113: **JAVIER, ELVIE D.** | D113: 9024431113 | F113: 7 | G113: 45894
A114: 716 | B114: PIZARRA, NIMFA M. | C114: **PIZARRA, NIMFA M.** | D114: 9024431164 | F114: 8 | G114: 45910
A115: 797 | B115: MARPURI, CHERRYLO M. | C115: **MARPURI, CHERRYLO M.** | D115: 9024431237 | F115: 9 | G115: 45925
A116: 877 | B116: ENGUERRA, ARLYN D. | C116: **ENGUERRA, ARLYN D.** | D116: 9024431245 | F116: 10 | G116: 45940
A117: 894 | B117: BATUSIS, MARILYN E. | C117: **BATUSIS, MARILYN E.** | D117: 9024431261 | F117: 11 | G117: 45955
A118: 114 | B118: OLASI, EMILY D. | C118: **OLASI, EMILY D.** | D118: 9024431296 | F118: 12 | G118: 45971
... A154: 467 | B154: JAURIGUE, JOAN V. | C154: **JAURIGUE, JOAN V.** | D154: 9024432349 | F154: 48 | G154: 46517
A155: 299 | B155: PASTORFIDE, ARLENE C. | C155: **PASTORFIDE, ARLENE C.** | D155: 9024432381 | G155: 46532
A156: 14267 | B156: BUENDIA, ELIZABETH E. | C156: **BUENDIA, ELIZABETH E.** | D156: 9024432403 | G156: 46548
A157: 391 | B157: ESCONDE, RAQUEL P. | C157: **ESCONDE, RAQUEL P.** | D157: 9024432411 | G157: 46563
A158: 163 | B158: DAJANG, ANABELLE A. | C158: **DAJANG, ANABELLE A.** | D158: 9024432438 | G158: 46578
A159: 345 | B159: DE ASIS, ARTEMIA M. | C159: **DE ASIS, ARTEMIA M.** | D159: 9024432446 | G159: 46593
A160: 126 | B160: ZABALA, CARINA M. | C160: **ZABALA, CARINA M.** | D160: 9024432454 | G160: 46609
A161: 9809 | B161: LAVADIA, MA. CECILIA R. | C161: **LAVADIA, MA. CECILIA R.** | D161: 9024432462 | G161: 46624
A162: 247 | B162: AMBAS, IMELDA G. | C162: **AMBAS, IMELDA G.** | D162: 9024432489 | G162: 46640
A163: 420 | B163: LOPEZ, ELOISA B. | C163: **LOPEZ, ELOISA B.** | D163: 9024432497 | G163: 46655
A164: 726 | B164: DE LEON, VERONICA E. | C164: **DE LEON, VERONICA E.** | D164: 9024432527 | G164: 46670
A165: 13800 | B165: LAJO, PRINCER JOAN L. | C165: **LAJO, PRINCER JOAN L.** | D165: 9024432551 | G165: 46685
A166: 175 | B166: EBORA, MARGARITA M. | C166: **EBORA, MARGARITA M.** | D166: 9024432586 | G166: 46701
... A169: 60 | B169: VELANDO, LUZ R. | C169: **VELANDO, LUZ R.** | D169: 9024535784 | G169: 46746
...
